Workbook

Sheet Assumptions
B1: SURF BETTING SCENARIO MODEL
B2: Back-of-Napkin Sizing | All figures illustrative
B4: PLATFORM ASSUMPTIONS
B5: Platform | C5: Max Bet / Event | D5: Events / Year | E5: Surf Available? | F5: Notes
B6: DraftKings | C6: 500 | D6: 11 | E6: Yes | F6: US primary; state-dependent
B7: FanDuel | C7: 500 | D7: 11 | E7: Yes | F7: US primary; sharp-friendly
B8: BetMGM | C8: 500 | D8: 11 | E8: Yes | F8: Fast to limit winners
B9: Bet365 | C9: 500 | D9: 11 | E9: Yes | F9: Gradual limiting
B10: Caesars | C10: 500 | D10: 11 | E10: Yes | F10: US; limited prop coverage
B11: BetUS | C11: 500 | D11: 11 | E11: Yes | F11: Offshore; higher limits possible
B12: TAB (Australia) | C12: 500 | D12: 11 | E12: Yes | F12: Deepest surf market
B13: Sportsbet (AU) | C13: 500 | D13: 11 | E13: Yes | F13: Australian market
B14: Total Platforms | C14: =COUNTA(B6:B13) -> 8
B16: MODEL EDGE ASSUMPTIONS
B17: Parameter | C17: Low (Conservative) | D17: Medium (Realistic) | E17: High (Optimistic)
B18: Model edge over market (% above break-even) | C18: 0.02 | D18: 0.05 | E18: 0.1
B19: Win rate on bets placed | C19: 0.52 | D19: 0.55 | E19: 0.6
B20: Avg odds on bets placed (decimal) | C20: 2 | D20: 2.5 | E20: 3
B21: Bets placed per event (across all platforms) | C21: 3 | D21: 6 | E21: 10
B22: Events bet on per year | C22: 8 | D22: 10 | E22: 11
B23: Average vig / juice | C23: 0.0476 | D23: 0.0476 | E23: 0.0476
B24: Platform utilization (% of platforms actually used) | C24: 0.5 | D24: 0.75 | E24: 1

Sheet Scenario Output
B1: SCENARIO OUTPUT — ANNUAL P&L ESTIMATE
B2: Assumes $500/event/platform max bet, 2026 WSL CT season
B4: CAPITAL DEPLOYED
B5: Metric | C5: Low | D5: Medium | E5: High
B6: Platforms used | C6: =ROUND(Assumptions!C14*Assumptions!C24,0) -> 4 | D6: =ROUND(Assumptions!C14*Assumptions!D24,0) -> 6 | E6: =ROUND(Assumptions!C14*Assumptions!E24,0) -> 8
B7: Bet size per platform per event | C7: =Assumptions!C6 -> 500 | D7: =Assumptions!C6 -> 500 | E7: =Assumptions!C6 -> 500
B8: Bets per event (total across platforms) | C8: =Assumptions!C21 -> 3 | D8: =Assumptions!D21 -> 6 | E8: =Assumptions!E21 -> 10
B9: Events bet on | C9: =Assumptions!C22 -> 8 | D9: =Assumptions!D22 -> 10 | E9: =Assumptions!E22 -> 11
B10: Total bets per year | C10: =C8*C9 -> 24 | D10: =D8*D9 -> 60 | E10: =E8*E9 -> 110
B11: Total capital wagered per year | C11: =C7*C10 -> 12000 | D11: =D7*D10 -> 30000 | E11: =E7*E10 -> 55000
B13: EXPECTED RETURNS (ANNUAL)
B14: Metric | C14: Low | D14: Medium | E14: High
B15: Average odds (decimal) | C15: =Assumptions!C20 -> 2 | D15: =Assumptions!D20 -> 2.5 | E15: =Assumptions!E20 -> 3
B16: Win rate | C16: =Assumptions!C19 -> 0.52 | D16: =Assumptions!D19 -> 0.55 | E16: =Assumptions!E19 -> 0.6
B17: Expected value per $1 bet (before vig) | C17: =(C15*C16)-1 -> 0.04 | D17: =(D15*D16)-1 -> 0.375 | E17: =(E15*E16)-1 -> 0.8
B18: Vig drag per $1 bet | C18: =Assumptions!C23 -> 0.0476 | D18: =Assumptions!D23 -> 0.0476 | E18: =Assumptions!E23 -> 0.0476
B19: Net EV per $1 bet (after vig) | C19: =C17-C18 -> -0.0076 | D19: =D17-D18 -> 0.3274 | E19: =E17-E18 -> 0.7524
B20: Gross winnings (wins × payout) | C20: =C10*C16*C7*C15 -> 12480 | D20: =D10*D16*D7*D15 -> 41250 | E20: =E10*E16*E7*E15 -> 99000
B21: Total wagered | C21: =C11 -> 12000 | D21: =D11 -> 30000 | E21: =E11 -> 55000
B22: Net profit (Gross - Wagered) | C22: =C20-C21 -> 480 | D22: =D20-D21 -> 11250 | E22: =E20-E21 -> 44000
B23: ROI (Net / Wagered) | C23: =IFERROR(C22/C21,0) -> 0.04 | D23: =IFERROR(D22/D21,0) -> 0.375 | E23: =IFERROR(E22/E21,0) -> 0.8
B25: MULTI-YEAR PROJECTION (Medium Scenario)
B26: Year | C26: Cumulative Wagered | D26: Cumulative Profit | E26: Cumulative ROI
B27: Year 1 | C27: =D21*1 -> 30000 | D27: =D22*1 -> 11250 | E27: =IFERROR(D27/C27,0) -> 0.375
B28: Year 2 | C28: =D21*2 -> 60000 | D28: =D22*2 -> 22500 | E28: =IFERROR(D28/C28,0) -> 0.375
B29: Year 3 | C29: =D21*3 -> 90000 | D29: =D22*3 -> 33750 | E29: =IFERROR(D29/C29,0) -> 0.375
B30: Year 4 | C30: =D21*4 -> 120000 | D30: =D22*4 -> 45000 | E30: =IFERROR(D30/C30,0) -> 0.375
B31: Year 5 | C31: =D21*5 -> 150000 | D31: =D22*5 -> 56250 | E31: =IFERROR(D31/C31,0) -> 0.375
B33: REALITY CHECK
B34: • These numbers assume consistent edge over time — edge decay is real and unmodeled here.
B35: • Getting limited on platforms will reduce effective platform count over time.
B36: • The 'High' scenario (10% edge, 60% win rate at 3.0 avg odds) is extremely optimistic.
B37: • The 'Low' scenario is the most honest starting expectation. Medium requires proven edge.
B38: • Variance is enormous — a 55% win rate means ~45% of bets lose. Drawdowns will happen.
B39: • No exchange markets exist for surf — sportsbook limitation risk is the binding constraint.
B40: • This model does NOT account for bankroll management / Kelly criterion sizing.
B42: BREAKEVEN ANALYSIS
B43: At These Avg Odds | C43: Breakeven Win Rate (incl. vig) | D43: Your Edge If Win Rate = 55% | E43: Profit at 55% / $500 / 60 bets
B44: 1.91 | C44: =(1/B44)*(1+Assumptions!C23) -> 0.54848168 | D44: =0.55-C44 -> 0.0015183246 | E44: =(0.55*B44*500*60)-(500*60) -> 1515
B45: 2 | C45: =(1/B45)*(1+Assumptions!C23) -> 0.5238 | D45: =0.55-C45 -> 0.0262 | E45: =(0.55*B45*500*60)-(500*60) -> 3000
...

Sheet Real Odds Examples
B1: REAL ODDS FROM NXTBETS DATA (2024-2025 CT Events)
B3: OUTRIGHT WINNER ODDS — 2024 Fiji Pro (Men's CT)
B4: Surfer | C4: Moneyline | D4: Decimal Odds | E4: Implied Prob | F4: If $500 Bet Wins | G4: Profit if Wins
B5: John John Florence | C5: 427 | D5: =(C5/100)+1 -> 5.27 | E5: =1/D5 -> 0.18975332 | F5: =D5*500 -> 2635 | G5: =F5-500 -> 2135
B6: Jack Robinson | C6: 546 | D6: =(C6/100)+1 -> 6.46 | E6: =1/D6 -> 0.15479876 | F6: =D6*500 -> 3230 | G6: =F6-500 -> 2730
B7: Gabriel Medina | C7: 611 | D7: =(C7/100)+1 -> 7.11 | E7: =1/D7 -> 0.14064698 | F7: =D7*500 -> 3555 | G7: =F7-500 -> 3055
B8: Griffin Colapinto | C8: 911 | D8: =(C8/100)+1 -> 10.11 | E8: =1/D8 -> 0.098911968 | F8: =D8*500 -> 5055 | G8: =F8-500 -> 4555
B9: Ethan Ewing | C9: 1182 | D9: =(C9/100)+1 -> 12.82 | E9: =1/D9 -> 0.07800312 | F9: =D9*500 -> 6410 | G9: =F9-500 -> 5910
B10: Italo Ferreira | C10: 1240 | D10: =(C10/100)+1 -> 13.4 | E10: =1/D10 -> 0.074626866 | F10: =D10*500 -> 6700 | G10: =F10-500 -> 6200
B13: OUTRIGHT WINNER ODDS — 2025 Pipe Pro (Men's CT)
B14: Surfer | C14: Moneyline | D14: Decimal Odds | E14: Implied Prob | F14: If $500 Bet Wins | G14: Profit if Wins
B15: Jack Robinson | C15: 544 | D15: =(C15/100)+1 -> 6.44 | E15: =1/D15 -> 0.1552795 | F15: =D15*500 -> 3220 | G15: =F15-500 -> 2720
B16: Filipe Toledo | C16: 730 | D16: =(C16/100)+1 -> 8.3 | E16: =1/D16 -> 0.12048193 | F16: =D16*500 -> 4150 | G16: =F16-500 -> 3650
B17: Griffin Colapinto | C17: 845 | D17: =(C17/100)+1 -> 9.45 | E17: =1/D17 -> 0.10582011 | F17: =D17*500 -> 4725 | G17: =F17-500 -> 4225
B18: Ethan Ewing | C18: 918 | D18: =(C18/100)+1 -> 10.18 | E18: =1/D18 -> 0.098231827 | F18: =D18*500 -> 5090 | G18: =F18-500 -> 4590
B19: Italo Ferreira | C19: 942 | D19: =(C19/100)+1 -> 10.42 | E19: =1/D19 -> 0.09596929 | F19: =D19*500 -> 5210 | G19: =F19-500 -> 4710
B20: Yago Dora | C20: 1477 | D20: =(C20/100)+1 -> 15.77 | E20: =1/D20 -> 0.063411541 | F20: =D20*500 -> 7885 | G20: =F20-500 -> 7385
B22: KEY INSIGHT: At these odds, a single correct outright winner bet at +900 on a $500 stake returns $4,500+ profit.
B23: But outright winners are rare (~10-15% implied probability for favorites). The edge must come from systematically identifying mispriced underdogs.

Sheet Max Aggression
B1: MAX AGGRESSION SCENARIO
B2: $1,000/platform × same bet on ALL platforms × 60% model accuracy
B4: ASSUMPTIONS
B5: Parameter | C5: Value
B6: Bet size per platform | C6: 1000
B7: Number of platforms (simultaneous) | C7: 8
B8: Capital per bet (all platforms) | C8: =C6*C7 -> 8000
B9: Bets per event | C9: 2
B10: Events per year (CT season) | C10: 11
B11: Total bet instances per year | C11: =C9*C10*C7 -> 176
B12: Total capital wagered per year | C12: =C6*C11 -> 176000
B13: Model win rate | C13: 0.6
B14: Average decimal odds on bets placed | C14: 2.5
B15: Vig / juice | C15: 0.0476
B17: ANNUAL RETURN BY AVERAGE ODDS TIER (60% win rate, $1K × 8 platforms, 22 bets/yr)
B18: Avg Decimal Odds | C18: Gross Winnings | D18: Total Wagered | E18: Net Profit | F18: ROI
B19: 1.91 | C19: =C13*B19*C8*(C9*C10) -> 201696 | D19: =C12 -> 176000 | E19: =C19-D19 -> 25696 | F19: =IFERROR(E19/D19,0) -> 0.146
B20: 2 | C20: =C13*B20*C8*(C9*C10) -> 211200 | D20: =C12 -> 176000 | E20: =C20-D20 -> 35200 | F20: =IFERROR(E20/D20,0) -> 0.2
B21: 2.5 | C21: =C13*B21*C8*(C9*C10) -> 264000 | D21: =C12 -> 176000 | E21: =C21-D21 -> 88000 | F21: =IFERROR(E21/D21,0) -> 0.5
B22: 3 | C22: =C13*B22*C8*(C9*C10) -> 316800 | D22: =C12 -> 176000 | E22: =C22-D22 -> 140800 | F22: =IFERROR(E22/D22,0) -> 0.8
B23: 4 | C23: =C13*B23*C8*(C9*C10) -> 422400 | D23: =C12 -> 176000 | E23: =C23-D23 -> 246400 | F23: =IFERROR(E23/D23,0) -> 1.4
B24: 5 | C24: =C13*B24*C8*(C9*C10) -> 528000 | D24: =C12 -> 176000 | E24: =C24-D24 -> 352000 | F24: =IFERROR(E24/D24,0) -> 2
B27: HEADLINE SCENARIO: 2.5 AVG ODDS
B28: Capital at risk per bet (across 8 platforms) | C28: =C8 -> 8000
B29: Total bets per year (bet instances) | C29: =C9*C10 -> 22
B30: Total capital wagered per year | C30: =C12 -> 176000
B31: Expected wins (60% of bets) | C31: =C13*C29 -> 13.2
B32: Expected losses | C32: =C29-C31 -> 8.8
B33: Gross payout from wins | C33: =C31*C14*C8 -> 264000
B34: Total staked | C34: =C30 -> 176000
B35: NET ANNUAL PROFIT | C35: =C33-C34 -> 88000
B36: ROI | C36: =IFERROR(C35/C34,0) -> 0.5
B38: SENSITIVITY: NET PROFIT BY WIN RATE (at 2.5 odds, $1K × 8 platforms)
B39: Win Rate | C39: Gross Payout | D39: Wagered | E39: Net Profit | F39: ROI
B40: 0.5 | C40: =B40*C14*C8*(C9*C10) -> 220000 | D40: =C12 -> 176000 | E40: =C40-D40 -> 44000 | F40: =IFERROR(E40/D40,0) -> 0.25
B41: 0.52 | C41: =B41*C14*C8*(C9*C10) -> 228800 | D41: =C12 -> 176000 | E41: =C41-D41 -> 52800 | F41: =IFERROR(E41/D41,0) -> 0.3
B42: 0.55 | C42: =B42*C14*C8*(C9*C10) -> 242000 | D42: =C12 -> 176000 | E42: =C42-D42 -> 66000 | F42: =IFERROR(E42/D42,0) -> 0.375
B43: 0.58 | C43: =B43*C14*C8*(C9*C10) -> 255200 | D43: =C12 -> 176000 | E43: =C43-D43 -> 79200 | F43: =IFERROR(E43/D43,0) -> 0.45
B44: 0.6 | C44: =B44*C14*C8*(C9*C10) -> 264000 | D44: =C12 -> 176000 | E44: =C44-D44 -> 88000 | F44: =IFERROR(E44/D44,0) -> 0.5
B45: 0.65 | C45: =B45*C14*C8*(C9*C10) -> 286000 | D45: =C12 -> 176000 | E45: =C45-D45 -> 110000 | F45: =IFERROR(E45/D45,0) -> 0.625
...
